Workbook

Sheet Faltantes febrero
A1: 7 | B1: LUSTRADORA | C1: SUPER SPEED | D1: Sin Modelo | F1: 43001000 | G1: QUIMICA MONTPELLIER S.A, - EDIF VIRREY LINIERS 667 | H1: ANDRADA | I1: BAJA
A2: 96 | B2: ASPIRADORA | C2: SUPER SPEED | D2: 101-P | E2: ELECTRICA | F2: 3234001000 | G2: ADIDAS CUYO | H2: FARIAS | J2: en reparación
A3: 101 | B3: ASPIRADORA MOCHILA | C3: CLARKE | D3: NAPSAC 424 | E3: ELECTRICA | F3: 3182003000 | G3: GMRA/ MIRGOR | J3: DADA DE BAJA
A4: 176 | B4: LUSTRADORA | C4: CLARKE | D4: C-15 | E4: ELECTRICA | F4: 43001000 | G4: QUIMICA MONTPELLIER S.A, - EDIF VIRREY LINIERS 667
A5: 219 | B5: ASPIRADORA | C5: TURBION | D5: T/67 | E5: ELECTRICA | F5: 165001000 | G5: Toyota Planta Zarate | H5: JEREMIAS | J5: NO ESTA EN EL SERVICIO
A6: 263 | B6: LAVADORA DE ALF.TRANSVERSAL | C6: CLARKE | D6: CM-12 | E6: ELECTRICA | F6: 1165000000 | G6: Banco Santa Fe Casa Central Rosario | H6: LUCIO RAMOS | J6: no está en el servicio
A7: 328 | B7: ASPIRADORA | C7: CLARKE | D7: 600 A | E7: ELECTRICA | F7: 1165005000 | G7: NUEVO BANCO DE SANTA FE S.A. - AGENCIA TRIBUNALES ROSARIO | H7: LUCIO RAMOS
A8: 372 | B8: ASPIRADORA | C8: SUPER SPEED | D8: 101-P | E8: ELECTRICA | F8: 1165003000 | G8: NUEVO BANCO DE SANTA FE S.A. - AGENCIA SAN MARTÍN | H8: LUCIO RAMOS
A9: 388 | B9: ASPIRADORA | C9: CLARKE | D9: 600 A | E9: ELECTRICA | F9: 1165067000 | G9: NUEVO BANCO DE SANTA FE S.A. - AGENCIA CAFERATTA | H9: LUCIO RAMOS
A10: 539 | B10: ASPIRADORA | C10: SUPER SPEED | D10: 101-P/A | E10: ELECTRICA | F10: 157004000 | G10: Banco de Valores Dep. Pompeya | H10: ORTIZ
A11: 563 | B11: LUSTRADORA | C11: SUPER SPEED | D11: P-28 | E11: ELECTRICA | F11: 3042074001 | G11: CEILING SOLUTIONS S.A. - Unibroker | H11: BAJA DEL SERVICIO
A12: 658 | B12: LUSTRADORA | C12: SUPER SPEED | D12: P-39 | E12: ELECTRICA | F12: 1532001000 | G12: Hospital Naval Bs As
A13: 752 | B13: ASPIRADORA | C13: SUPER SPEED | D13: 101-P | E13: ELECTRICA | F13: 1165112000 | G13: NUEVO BANCO DE SANTA FE S.A. - EDIF SARGENTO CABRAL 156 | H13: LUCIO RAMOS
A14: 757 | B14: ASPIRADORA | C14: SUPER SPEED | D14: 101-P/A | E14: ELECTRICA | F14: 165001000 | G14: Toyota Planta Zarate | H14: JEREMIAS | J14: NO ESTA EN EL SERVICIO
A15: 930 | B15: LUSTRADORA | C15: SUPER SPEED | D15: P-28 | E15: ELECTRICA | F15: 3178001000 | G15: INTI - RETIRO
A16: 931 | B16: LUSTRADORA | C16: DIXTER | D16: 1014 | E16: ELECTRICA | F16: 212005000 | G16: ALTIRA Edif. San Martin | H16: ORTIZ
A17: 934 | B17: ASPIRADORA | C17: CLARKE | D17: 600 A | E17: ELECTRICA | F17: 1165001000 | G17: NUEVO BANCO DE SANTA FE S.A. - AGENCIA ECHESORTU | H17: LUCIO RAMOS
A18: 965 | B18: LUSTRADORA | C18: DIXTER | D18: Sin Modelo | E18: ELECTRICA | F18: 1165000000 | G18: Banco Santa Fe Casa Central Rosario | H18: LUCIO RAMOS | J18: no está en el servicio
A19: 1114 | B19: LUSTRADORA | C19: CLARKE | D19: FM 1500 | E19: ELECTRICA | F19: 3319002000 | G19: Banco Prov. B.A. San Martin 108 | H19: MITOLO | J19: no esta
A20: 1121 | B20: LUSTRADORA | C20: SUPER SPEED | D20: P-39 | E20: ELECTRICA | F20: 3042116001 | G20: Distribuidora Cañon | H20: ALE GAONA | J20: NO ESTA EN EL SERVICIO
A21: 1182 | B21: LAVADORA DE ALFOMBRA ROTATIVA | C21: SUPER SPEED | D21: P-39 | E21: ELECTRICA | F21: 3223006000 | G21: CLICOH EXPRESS S.A.S - ALEJANDRO M. CERVANTES 1433 | H21: BAJA DEL SERVICIO
A22: 1349 | B22: LUSTRADORA | C22: SUPER SPEED | D22: P-39 | E22: ELECTRICA | F22: 165001000 | G22: Toyota Planta Zarate | H22: JEREMIAS | J22: NO ESTA EN EL SERVICIO
A23: 1354 | B23: LUSTRADORA | C23: DIXTER | D23: Sin Modelo | E23: ELECTRICA | F23: 1925001000 | G23: Loma Negra Vicente Casares | H23: Leo Baez | J23: no está en el servicio
A24: 1465 | B24: ASPIRADORA | C24: SUPER SPEED | D24: 101-P | E24: ELECTRICA | F24: 1068021000 | G24: SOUTHBAY SRL - PASEO ALCORTA | H24: ALE GAONA
A25: 1633 | B25: ASPIRADORA | C25: SUPER SPEED | D25: 101-P | E25: ELECTRICA | F25: 212005000 | G25: ALTIRA Edif. San Martin | H25: ORTIZ
A26: 1715 | B26: ASPIRADORA | C26: SUPER SPEED | D26: 101-P | E26: ELECTRICA | F26: 1532001000 | G26: Hospital Naval Bs As
A27: 1955 | B27: ASPIRADORA | C27: SUPER SPEED | D27: 101-P/A | E27: ELECTRICA | F27: 1967007000 | G27: Jones Lang Google Ali | H27: SABINA LEIVA | J27: no está en el servicio
A28: 2009 | B28: ASPIRADORA | C28: SIRIO | D28: YES 215 | E28: ELECTRICA | F28: 1014007 | G28: Limpiolux Maq. Córdoba | H28: JEREMIAS | J28: NO ESTA EN EL SERVICIO
A29: 2012 | B29: ASPIRADORA | C29: SIRIO | D29: YES 215 | E29: ELECTRICA | F29: 3073001000 | G29: MOLINOS BENVENUTO S.A - EDIFICIO CATAMARCA 1053 | H29: LUCIO RAMOS
A30: 2028 | B30: ASPIRADORA | C30: SIRIO | D30: YES 215 | E30: ELECTRICA | F30: 1165000000 | G30: Banco Santa Fe Casa Central Rosario | H30: LUCIO RAMOS | J30: no está en el servicio
A31: 2053 | B31: LUSTRADORA | C31: SUPER SPEED | D31: P-39 | E31: ELECTRICA | F31: 1165000000 | G31: Banco Santa Fe Casa Central Rosario | H31: LUCIO RAMOS | J31: no está en el servicio
A32: 2065 | B32: LUSTRADORA | C32: SUPER SPEED | D32: P-28 | E32: ELECTRICA | F32: 1493003000 | G32: Prisma Medios de pagos | H32: JEREMIAS | J32: Donada a cliente (Eduardo Souza año 2003)
A33: 2113 | B33: ASPIRADORA | C33: SIRIO | D33: YES 215 | E33: ELECTRICA | F33: 1165116000 | G33: NUEVO BANCO DE SANTA FE S.A. - CALL CENTER RIOJA 920 - ROSARIO | H33: LUCIO RAMOS
A34: 2146 | B34: LUSTRADORA | C34: DIXTER | D34: Sin Modelo | E34: ELECTRICA | F34: 2081002000 | G34: EXTERNAL MARKET S.R.L. - SARGENTO CABRAL 4235 - MUNRO | H34: BAJA DEL SERVICIO
A35: 2146 | B35: LUSTRADORA | C35: DIXTER | D35: Sin Modelo | E35: ELECTRICA | F35: 2081002000 | G35: EXTERNAL MARKET S.R.L. - SARGENTO CABRAL 4235 - MUNRO | H35: BAJA DEL SERVICIO
A36: 2267 | B36: ASPIRADORA | C36: SIRIO | D36: AIR FORCE X 1 | E36: ELECTRICA | F36: 1014007 | G36: Limpiolux Maq. Córdoba | H36: JEREMIAS | J36: NO ESTA EN EL SERVICIO
A37: 2274 | B37: LAVADORA DE ALFOMBRA ROTATIVA | C37: DIXTER | D37: S.KLINER | E37: ELECTRICA | F37: 2548017000 | G37: Telecentro Luis Guillon | H37: BANEGA | J37: no está en el servicio
A38: 2314 | B38: FREGADORA ELECTRICA | C38: SUPER SCRUBBER | D38: S20 E | E38: ELECTRICA | F38: 3316001000 | G38: UNION TRAB GASTR REP ARG SECC AVELLANEDADELEGACION TEMPERLEY-CASA PARTICULAR –Dorrego 539 | H38: BAJA DEL SERVICIO
A39: 2329 | B39: ASPIRADORA | C39: SUPER SPEED | D39: 101-P | E39: ELECTRICA | F39: 1165000000 | G39: Banco Santa Fe Casa Central Rosario | H39: LUCIO RAMOS | J39: no está en el servicio
A40: 2540 | B40: HIDROLAVADORA A.FRIA ELECTRICA | C40: NILFISK | D40: ALTO POSEIDON 3 | E40: ELECTRICA | F40: 1165000000 | G40: Banco Santa Fe Casa Central Rosario
...

Sheet Inventario ENE 30-1-26
A1: Nro Inventario | B1: Inventario de Maquinarias por Nro.Descripción | C1: Marcas.Descripción | D1: Modelos.Descripción | E1: Serie | F1: Fecha de Incorporación | G1: Casa | H1: Nombre de casa | I1: Unidad de negocio | J1: Potencia W
A2: 5 | B2: LUSTRADORA | C2: SUPER SPEED | D2: P-39 | F2: 25688 | G2: 3135001000 | H2: CELSUR - GRAL RODRIGUEZ | I2: LIMPIOLUX | J2: 309.5
A3: 6 | B3: LUSTRADORA | C3: SUPER SPEED | D3: P-39 | F3: 36773 | G3: 3370003000 | H3: ANAC - EZEIZA Centro de Instrucción, perfeccionamiento y experimentación CIPE Aerop. M. Pistarini | I3: LIMPIOLUX | J3: 309.5
A4: 7 | B4: LUSTRADORA | C4: SUPER SPEED | D4: Sin Modelo | F4: 25688 | G4: 43001000 | H4: QUIMICA MONTPELLIER S.A, - EDIF VIRREY LINIERS 667 | I4: LIMPIOLUX | J4: 1212
A5: 8 | B5: LUSTRADORA | C5: SUPER SPEED | D5: Sin Modelo | F5: 27760 | G5: 165005000 | H5: TOYOTA ARGENTINA S.A.. - OF MARTINEZ | I5: LIMPIOLUX | J5: 1212
A6: 11 | B6: LAVADORA DE ALFOMBRA ROTATIVA | C6: DIXTER | D6: P-39 | E6: 42617 | F6: 25688 | G6: 66011000 | H6: CENCOSUD S.A., - UNICENTER SHOPPING | I6: LIMPIOLUX | J6: 318.5
A7: 18 | B7: ASPIRADORA | C7: CLARKE | D7: 600 A | E7: 117405 | F7: 25688 | G7: 212007000 | H7: A.T.I.L.R.A. - EDIFICIO BOATTI 140 - MORON | I7: LIMPIOLUX | J7: 1091
A8: 23 | B8: LUSTRADORA | C8: DIXTER | D8: Sin Modelo | F8: 25688 | G8: 3207001000 | H8: DIRECCION NACIONAL DE VIALIDAD - REGION 1 - BUENOS AIRES CABA | I8: LIMPIOLUX | J8: 1154
A9: 26 | B9: LUSTRADORA | C9: SUPER SPEED | D9: P-39 | E9: 9814 | F9: 25688 | G9: 43006000 | H9: QUIMICA MONTPELLIER S.A, - POLO FARMACEUTICO | I9: LIMPIOLUX | J9: 309.5
A10: 30 | B10: ASPIRADORA | C10: DIXTER | D10: A.18 | F10: 25688 | G10: 1068020000 | H10: SOUTHBAY SRL-Alto Avellaneda Shopping | I10: LIMPIOLUX
A11: 31 | B11: ASPIRADORA | C11: CLARKE | D11: 600 A | F11: 25688 | G11: 43006000 | H11: QUIMICA MONTPELLIER S.A, - POLO FARMACEUTICO | I11: LIMPIOLUX | J11: 1091
A12: 35 | B12: ASPIRADORA | C12: CLARKE | D12: 600 A | E12: 115350 | F12: 25688 | G12: 2886003000 | H12: CRANE WORLDWIDE LOGISTICS ARGENTINA S.A. - OF. ESTADOS UNIDOS 20 - Piso 3° | I12: LIMPIOLUX | J12: 1091
A13: 40 | B13: LUSTRADORA | C13: SUPER SPEED | D13: P-39 | E13: 722 | F13: 25688 | G13: 2126001000 | H13: MINISTERIO DE HACIENDA - CASA CENTRAL - YRIGOYEN 250 | I13: LIMPIOLUX | J13: 309.5
A14: 41 | B14: LUSTRADORA | C14: SUPER SPEED | D14: P-39 | E14: 1223 | F14: 25688 | G14: 66011000 | H14: CENCOSUD S.A., - UNICENTER SHOPPING | I14: LIMPIOLUX | J14: 309.5
A15: 46 | B15: LUSTRADORA | C15: SUPER SPEED | D15: P-39 | E15: 1489 | F15: 25688 | G15: 2798001000 | H15: SINERGIUM BIOTECH S.A. - PLANTA GARIN | I15: LIMPIOLUX | J15: 309.5
A16: 49 | B16: LUSTRADORA | C16: SUPER SPEED | D16: P-28 | E16: 15620 | F16: 25688 | G16: 2548095000 | H16: TELECENTRO S.A. - MALVINAS - FELIX DE OLAZABAL 150 | I16: LIMPIOLUX | J16: 461
A17: 56 | B17: ASPIRADORA | C17: SUPER SPEED | D17: 101-P/A | E17: 13787 | F17: 25688 | G17: 3288001000 | H17: LX ARGENTINA | I17: LIMPIOLUX | J17: 1212
A18: 62 | B18: LAVADORA DE ALFOMBRA ROTATIVA | C18: SUPER SPEED | D18: P-39 | E18: 2 | F18: 25688 | G18: 1165000000 | H18: NUEVO BANCO DE SANTA FE S.A. - CASA CENTRAL ROSARIO | I18: LIMPIOLUX | J18: 309.5
A19: 65 | B19: LUSTRADORA | C19: SUPER SPEED | D19: P-39 | E19: 5 | F19: 25688 | G19: 66031000 | H19: CENCOSUD S.A., - CENTRO DE DISTRIBUCION EZEIZA | I19: LIMPIOLUX | J19: 309.5
A20: 66 | B20: LAVADORA DE ALFOMBRA ROTATIVA | C20: SUPER SPEED | D20: P-39 | E20: 4062 | F20: 25688 | G20: 3042104001 | H20: CEILING SOLUTIONS S.A. - FRIGORIFICO RIOSMA SOCIEDAD ANONIMA - EDIF. MATADEROS | I20: CEILING | J20: 309.5
A21: 68 | B21: LUSTRADORA | C21: DIXTER | D21: Sin Modelo | E21: 1047258 | F21: 25688 | G21: 3328001000 | H21: AL RIO SPORT CLUB SAN ISIDRO | I21: CEILING | J21: 1154
A22: 85 | B22: LAVADORA DE ALFOMBRA ROTATIVA | C22: SUPER SPEED | D22: P-39 | E22: 6966 | F22: 25688 | G22: 3116001000 | H22: GIRE - AV CASEROS | I22: LIMPIOLUX | J22: 309.5
A23: 87 | B23: LAVADORA DE ALFOMBRA ROTATIVA | C23: SUPER SPEED | D23: P-39 | E23: 6786 | F23: 25688 | G23: 1165000000 | H23: NUEVO BANCO DE SANTA FE S.A. - CASA CENTRAL ROSARIO | I23: LIMPIOLUX | J23: 309.5
A24: 90 | B24: LAVADORA DE ALFOMBRA ROTATIVA | C24: DIXTER | D24: Sin Modelo | F24: 25688 | G24: 153002000 | H24: ABBOTT LABORATORIES ARGENTINA S.A.. - ABBOTT PLANTA | I24: LIMPIOLUX | J24: 1154
A25: 91 | B25: LUSTRADORA | C25: DIXTER | D25: S.KLINER | F25: 25688 | G25: 66032000 | H25: CENCOSUD S.A., - PLANTA DE CARNES - EZEIZA | I25: LIMPIOLUX | J25: 532
A26: 92 | B26: LUSTRADORA | C26: DIXTER | D26: Sin Modelo | E26: 3852 | F26: 25688 | G26: 1014002 | H26: LIMPIOLUX S. A. - C. I. M. REPARACIONES | J26: 1154
A27: 94 | B27: LUSTRADORA | C27: SUPER SPEED | D27: E-39 | F27: 25688 | G27: 2126001000 | H27: MINISTERIO DE HACIENDA - CASA CENTRAL - YRIGOYEN 250 | I27: LIMPIOLUX | J27: 309.5
A28: 96 | B28: ASPIRADORA | C28: SUPER SPEED | D28: 101-P | E28: 13761 | F28: 25688 | G28: 3234001000 | H28: CUSHMAN & WAKEFIELD ARGENTINA SRL - ADIDAS CUYO - SAN ISIDRO | I28: LIMPIOLUX | J28: 1212
A29: 97 | B29: ASPIRADORA | C29: TURBION | D29: T/66 | F29: 25688 | G29: 18001000 | H29: BOLSA DE COMERCIO DE BUENOS AIRES - EDIF SARMIENTO 299 | I29: LIMPIOLUX | J29: 1202.5
A30: 102 | B30: ASPIRADORA | C30: CLARKE | D30: 600 A | E30: 117012 | F30: 25688 | G30: 1014001 | H30: LIMPIOLUX S. A. - C. I. M. STOCK | J30: 1091
A31: 103 | B31: ASPIRADORA | C31: SUPER SPEED | D31: 101-P | E31: 8197 | F31: 25688 | G31: 1014001 | H31: LIMPIOLUX S. A. - C. I. M. STOCK | J31: 1212
A32: 104 | B32: ASPIRADORA | C32: SUPER SPEED | D32: 101-P | E32: 13742 | F32: 25688 | G32: 2958001000 | H32: METAGAL ARGENTINA S.A. - EDIFICIO VILLA DE MAYO | I32: LIMPIOLUX | J32: 1212
A33: 106 | B33: LUSTRADORA | C33: SUPER SPEED | D33: P-39 | E33: 7403 | F33: 25688 | G33: 1014001 | H33: LIMPIOLUX S. A. - C. I. M. STOCK | J33: 309.5
A34: 109 | B34: LAVADORA DE ALFOMBRA ROTATIVA | C34: SUPER SPEED | D34: P-39 | E34: 628 | F34: 25688 | G34: 1014001 | H34: LIMPIOLUX S. A. - C. I. M. STOCK | J34: 309.5
A35: 112 | B35: LUSTRADORA | C35: DIXTER | D35: S.KLINER | F35: 25688 | G35: 2558002000 | H35: FIDEISALUD S.A. - Bartolome Mitre 1375 | I35: LIMPIOLUX | J35: 532
A36: 113 | B36: ASPIRADORA | C36: DIXTER | D36: 2815 | F36: 25688 | G36: 66031000 | H36: CENCOSUD S.A., - CENTRO DE DISTRIBUCION EZEIZA | I36: LIMPIOLUX | J36: 1154
A37: 119 | B37: ASPIRADORA | C37: CLARKE | D37: 600 A | F37: 25688 | G37: 1165004000 | H37: NUEVO BANCO DE SANTA FE S.A. - AGENCIA AYACUCHO | I37: LIMPIOLUX | J37: 1091
A38: 120 | B38: ASPIRADORA | C38: SUPER SPEED | D38: 101-P | E38: 4097 | F38: 25688 | G38: 1507003000 | H38: AGROFARM S.A. - EDIF MORENO 957 - PISO 10º | I38: LIMPIOLUX | J38: 1212
A39: 123 | B39: LAVADORA DE ALFOMBRA ROTATIVA | C39: DIXTER | D39: Sin Modelo | F39: 25688 | G39: 165001000 | H39: TOYOTA ARGENTINA S.A.. - PLANTA ZARATE | I39: LIMPIOLUX | J39: 1154
A40: 124 | B40: LUSTRADORA | C40: CLARKE | D40: FM 1700 | F40: 25688 | G40: 1000012 | H40: LIMPIOLUX S. A. - LIMPIOLUX S. A. - GERENCIA (PEÑA) | J40: 629
...

Sheet Inventario FEB 4-3-26
A1: Nro Inventario | B1: Potencia W
A2: 5 | B2: =VLOOKUP(A2,'Inventario ENE 30-1-26'!$A$1:$J$10000,10,FALSE) -> 309.5
A3: 6 | B3: =VLOOKUP(A3,'Inventario ENE 30-1-26'!$A$1:$J$10000,10,FALSE) -> 309.5
A4: 7 | B4: =VLOOKUP(A4,'Inventario ENE 30-1-26'!$A$1:$J$10000,10,FALSE) -> 1212
A5: 8 | B5: =VLOOKUP(A5,'Inventario ENE 30-1-26'!$A$1:$J$10000,10,FALSE) -> 1212
A6: 11 | B6: =VLOOKUP(A6,'Inventario ENE 30-1-26'!$A$1:$J$10000,10,FALSE) -> 318.5
A7: 18 | B7: =VLOOKUP(A7,'Inventario ENE 30-1-26'!$A$1:$J$10000,10,FALSE) -> 1091
A8: 23 | B8: =VLOOKUP(A8,'Inventario ENE 30-1-26'!$A$1:$J$10000,10,FALSE) -> 1154
A9: 26 | B9: =VLOOKUP(A9,'Inventario ENE 30-1-26'!$A$1:$J$10000,10,FALSE) -> 309.5
A10: 30 | B10: =VLOOKUP(A10,'Inventario ENE 30-1-26'!$A$1:$J$10000,10,FALSE) -> 0
A11: 31 | B11: =VLOOKUP(A11,'Inventario ENE 30-1-26'!$A$1:$J$10000,10,FALSE) -> 1091
A12: 35 | B12: =VLOOKUP(A12,'Inventario ENE 30-1-26'!$A$1:$J$10000,10,FALSE) -> 1091
A13: 40 | B13: =VLOOKUP(A13,'Inventario ENE 30-1-26'!$A$1:$J$10000,10,FALSE) -> 309.5
... A657: 2170 | B657: =VLOOKUP(A657,'Inventario ENE 30-1-26'!$A$1:$J$10000,10,FALSE) -> 12
A658: 2175 | B658: 0
A659: 2180 | B659: =VLOOKUP(A659,'Inventario ENE 30-1-26'!$A$1:$J$10000,10,FALSE) -> 309.5
A660: 2181 | B660: =VLOOKUP(A660,'Inventario ENE 30-1-26'!$A$1:$J$10000,10,FALSE) -> 24
A661: 2182 | B661: =VLOOKUP(A661,'Inventario ENE 30-1-26'!$A$1:$J$10000,10,FALSE) -> 629
A662: 2183 | B662: =VLOOKUP(A662,'Inventario ENE 30-1-26'!$A$1:$J$10000,10,FALSE) -> 1212
A663: 2194 | B663: =VLOOKUP(A663,'Inventario ENE 30-1-26'!$A$1:$J$10000,10,FALSE) -> 309.5
A664: 2195 | B664: =VLOOKUP(A664,'Inventario ENE 30-1-26'!$A$1:$J$10000,10,FALSE) -> 309.5
A665: 2196 | B665: =VLOOKUP(A665,'Inventario ENE 30-1-26'!$A$1:$J$10000,10,FALSE) -> 309.5
A666: 2200 | B666: =VLOOKUP(A666,'Inventario ENE 30-1-26'!$A$1:$J$10000,10,FALSE) -> 309.5
A667: 2201 | B667: =VLOOKUP(A667,'Inventario ENE 30-1-26'!$A$1:$J$10000,10,FALSE) -> 1164.5
A668: 2202 | B668: =VLOOKUP(A668,'Inventario ENE 30-1-26'!$A$1:$J$10000,10,FALSE) -> 309.5
A669: 2203 | B669: =VLOOKUP(A669,'Inventario ENE 30-1-26'!$A$1:$J$10000,10,FALSE) -> 1164.5
A670: 2204 | B670: =VLOOKUP(A670,'Inventario ENE 30-1-26'!$A$1:$J$10000,10,FALSE) -> 1212
... A789: 2697 | B789: =VLOOKUP(A789,'Inventario ENE 30-1-26'!$A$1:$J$10000,10,FALSE) -> 3400
A790: 2710 | B790: 0
A791: 2712 | B791: =VLOOKUP(A791,'Inventario ENE 30-1-26'!$A$1:$J$10000,10,FALSE) -> 2000
A792: 2714 | B792: =VLOOKUP(A792,'Inventario ENE 30-1-26'!$A$1:$J$10000,10,FALSE) -> 3400
A793: 2716 | B793: =VLOOKUP(A793,'Inventario ENE 30-1-26'!$A$1:$J$10000,10,FALSE) -> 1000
A794: 2717 | B794: =VLOOKUP(A794,'Inventario ENE 30-1-26'!$A$1:$J$10000,10,FALSE) -> 1000
A795: 2723 | B795: =VLOOKUP(A795,'Inventario ENE 30-1-26'!$A$1:$J$10000,10,FALSE) -> 1000
A796: 2724 | B796: =VLOOKUP(A796,'Inventario ENE 30-1-26'!$A$1:$J$10000,10,FALSE) -> 1000
A797: 2725 | B797: =VLOOKUP(A797,'Inventario ENE 30-1-26'!$A$1:$J$10000,10,FALSE) -> 1000
A798: 2726 | B798: =VLOOKUP(A798,'Inventario ENE 30-1-26'!$A$1:$J$10000,10,FALSE) -> 309.5
A799: 2730 | B799: 0
A800: 2731 | B800: 0
A801: 2732 | B801: 0
...
